<?xml version="1.0" ?>
<!-- =================================================================================== -->
<!-- |    This document was autogenerated by xacro from myrobot.urdf.xacro             | -->
<!-- |    EDITING THIS FILE BY HAND IS NOT RECOMMENDED                                 | -->
<!-- =================================================================================== -->
<robot name="myrobot">
  <material name="black">
    <color rgba="0.0 0.0 0.0 1.0"/>
  </material>
  <material name="blue">
    <color rgba="0.0 0.0 0.8 1.0"/>
  </material>
  <material name="green">
    <color rgba="0.0 0.8 0.0 1.0"/>
  </material>
  <material name="grey">
    <color rgba="0.2 0.2 0.2 1.0"/>
  </material>
  <material name="orange">
    <color rgba="1.0 0.4235294117647059 0.0392156862745098 1.0"/>
  </material>
  <material name="brown">
    <color rgba="0.8705882352941177 0.8117647058823529 0.7647058823529411 1.0"/>
  </material>
  <material name="red">
    <color rgba="0.8 0.0 0.0 1.0"/>
  </material>
  <material name="white">
    <color rgba="1.0 1.0 1.0 1.0"/>
  </material>
  <material name="silver">
    <color rgba="0.79 0.82 0.93 1"/>
  </material>
  <material name="dark_grey">
    <color rgba="0.3 0.3 0.3 1"/>
  </material>
  <!-- =============== Inertial macros =============== -->
  <!-- =============== Base macros =============== -->
  <link name="base_link"/>
  <link name="chassis">
    <visual>
      <origin rpy="0.0 0.0 0.0" xyz="0.0 0.0 0.0"/>
      <geometry>
        <box size="0.15 0.1 0.05"/>
      </geometry>
      <material name="silver"/>
    </visual>
    <collision>
      <origin rpy="0.0 0.0 0.0" xyz="0.0 0.0 0.0"/>
      <geometry>
        <box size="0.15 0.1 0.05"/>
      </geometry>
    </collision>
    <inertial>
      <mass value="0.01"/>
      <inertia ixx="1.041666666666667e-05" ixy="0.0" ixz="0.0" iyy="2.0833333333333336e-05" iyz="0.0" izz="2.7083333333333335e-05"/>
      <origin rpy="0.0 0.0 0.0" xyz="0.0 0.0 0.0"/>
    </inertial>
  </link>
  <link name="ballcaster">
    <visual>
      <geometry>
        <sphere radius="0.008099999999999996"/>
      </geometry>
      <material name="grey"/>
    </visual>
    <collision>
      <geometry>
        <sphere radius="0.008099999999999996"/>
      </geometry>
    </collision>
    <inertial>
      <mass value="0.2"/>
      <inertia ixx="5.2487999999999945e-06" ixy="0.0" ixz="0.0" iyy="5.2487999999999945e-06" iyz="0.0" izz="5.2487999999999945e-06"/>
    </inertial>
  </link>
  <link name="left_wheel">
    <visual>
      <geometry>
        <mesh filename="file:///ros_ws/src/myrobot_description/meshes/wheel.stl"/>
      </geometry>
      <material name="brown"/>
    </visual>
    <collision>
      <origin rpy="0 0 0" xyz="0 0 0"/>
      <geometry>
        <cylinder length="0.025" radius="0.0331"/>
      </geometry>
    </collision>
    <inertial>
      <mass value="0.05"/>
      <inertia ixx="1.6299291666666667e-05" ixy="0" ixz="0" iyy="1.6299291666666667e-05" iyz="0" izz="2.7390249999999997e-05"/>
      <origin rpy="0.0 0.0 0.0" xyz="0.0 0.0 0.0"/>
    </inertial>
  </link>
  <link name="right_wheel">
    <visual>
      <geometry>
        <mesh filename="file:///ros_ws/src/myrobot_description/meshes/wheel.stl"/>
      </geometry>
      <material name="brown"/>
    </visual>
    <collision>
      <origin rpy="0 0 0" xyz="0 0 0"/>
      <geometry>
        <cylinder length="0.025" radius="0.0331"/>
      </geometry>
    </collision>
    <inertial>
      <mass value="0.05"/>
      <inertia ixx="1.6299291666666667e-05" ixy="0" ixz="0" iyy="1.6299291666666667e-05" iyz="0" izz="2.7390249999999997e-05"/>
      <origin rpy="0.0 0.0 0.0" xyz="0.0 0.0 0.0"/>
    </inertial>
  </link>
  <!-- ===== JOINTS ===== -->
  <joint name="base_chasis" type="fixed">
    <origin rpy="0 0 0" xyz="0 0 0.0331"/>
    <parent link="base_link"/>
    <child link="chassis"/>
  </joint>
  <joint name="base_ballcaster" type="fixed">
    <origin rpy="0 0 0" xyz="-0.06285 0 -0.025"/>
    <parent link="chassis"/>
    <child link="ballcaster"/>
  </joint>
  <joint name="base_left_wheel" type="continuous">
    <origin rpy="1.57 0.0 0.0" xyz="0.034999999999999996 0.065 0.0"/>
    <parent link="chassis"/>
    <child link="left_wheel"/>
    <axis xyz="0 0 -1"/>
    <limit effort="100" velocity="100.0"/>
  </joint>
  <joint name="base_right_wheel" type="continuous">
    <origin rpy="-1.57 0.0 0.0" xyz="0.034999999999999996 -0.065 0.0"/>
    <parent link="chassis"/>
    <child link="right_wheel"/>
    <axis xyz="0 0 1"/>
    <limit effort="100" velocity="100.0"/>
  </joint>
  <gazebo>
    <plugin filename="libgazebo_ros_control.so" name="gazebo_ros_control">
    
            </plugin>
  </gazebo>
  <gazebo>
    <plugin filename="libgazebo_ros_diff_drive.so" name="differential_drive_controller">
      <!-- Plugin update rate in Hz -->
      <updateRate>30</updateRate>
      <!-- Name of left joint, defaults to `left_joint` -->
      <leftJoint>base_left_wheel</leftJoint>
      <!-- Name of right joint, defaults to `right_joint` -->
      <rightJoint>base_right_wheel</rightJoint>
      <!-- The distance from the center of one wheel to the other, in meters, defaults to 0.34 m -->
      <wheelSeparation>0.125</wheelSeparation>
      <!-- Diameter of the wheels, in meters, defaults to 0.15 m -->
      <wheelDiameter>0.0662</wheelDiameter>
      <!-- Wheel acceleration, in rad/s^2, defaults to 0.0 rad/s^2 -->
      <wheelAcceleration>1.0</wheelAcceleration>
      <!-- Maximum torque which the wheels can produce, in Nm, defaults to 5 Nm -->
      <wheelTorque>20</wheelTorque>
      <!-- Topic to receive geometry_msgs/Twist message commands, defaults to `cmd_vel` -->
      <commandTopic>cmd_vel</commandTopic>
      <!-- Topic to publish nav_msgs/Odometry messages, defaults to `odom` -->
      <odometryTopic>odom</odometryTopic>
      <!-- Odometry frame, defaults to `odom` -->
      <odometryFrame>odom</odometryFrame>
      <!-- Robot frame to calculate odometry from, defaults to `base_footprint` -->
      <robotBaseFrame>base_link</robotBaseFrame>
      <!-- Odometry source, 0 for ENCODER, 1 for WORLD, defaults to WORLD -->
      <odometrySource>1</odometrySource>
      <!-- Set to true to publish transforms for the wheel links, defaults to false -->
      <publishWheelTF>true</publishWheelTF>
      <!-- Set to true to publish transforms for the odometry, defaults to true -->
      <publishOdom>true</publishOdom>
      <!-- Set to true to publish sensor_msgs/JointState on /joint_states for the wheel joints, defaults to false -->
      <publishWheelJointState>true</publishWheelJointState>
      <!-- Set to true to swap right and left wheels, defaults to true -->
      <legacyMode>false</legacyMode>
    </plugin>
  </gazebo>
  <gazebo reference="left_wheel">
    <mu1 value="200"/>
    <mu2 value="200"/>
    <kp value="10000000.0"/>
    <kd value="1.0"/>
    <minDepth>0.01</minDepth>
  </gazebo>
  <gazebo reference="right_wheel">
    <mu1 value="200"/>
    <mu2 value="200"/>
    <kp value="10000000.0"/>
    <kd value="1.0"/>
    <minDepth>0.01</minDepth>
  </gazebo>
  <gazebo reference="ballcaster">
    <mu1 value="200"/>
    <mu2 value="200"/>
    <kp value="10000000.0"/>
    <kd value="1.0"/>
    <minDepth>0.01</minDepth>
  </gazebo>
</robot>
